[2023-12-03 22:53:25,840] {taskinstance.py:1159} INFO - Dependencies all met for <TaskInstance: water_polution.model_preparation manual__2023-12-03T17:38:00.239033+00:00 [queued]>
[2023-12-03 22:53:25,848] {taskinstance.py:1159} INFO - Dependencies all met for <TaskInstance: water_polution.model_preparation manual__2023-12-03T17:38:00.239033+00:00 [queued]>
[2023-12-03 22:53:25,848] {taskinstance.py:1356} INFO - 
--------------------------------------------------------------------------------
[2023-12-03 22:53:25,848] {taskinstance.py:1357} INFO - Starting attempt 1 of 6
[2023-12-03 22:53:25,848] {taskinstance.py:1358} INFO - 
--------------------------------------------------------------------------------
[2023-12-03 22:53:25,876] {taskinstance.py:1377} INFO - Executing <Task(BashOperator): model_preparation> on 2023-12-03 17:38:00.239033+00:00
[2023-12-03 22:53:25,881] {standard_task_runner.py:52} INFO - Started process 20539 to run task
[2023-12-03 22:53:25,896] {standard_task_runner.py:79} INFO - Running: ['airflow', 'tasks', 'run', 'water_polution', 'model_preparation', 'manual__2023-12-03T17:38:00.239033+00:00', '--job-id', '13', '--raw', '--subdir', 'DAGS_FOLDER/water_polution.py', '--cfg-path', '/tmp/tmpgr_q8ixx', '--error-file', '/tmp/tmp3o9syog7']
[2023-12-03 22:53:25,896] {standard_task_runner.py:80} INFO - Job 13: Subtask model_preparation
[2023-12-03 22:53:25,969] {task_command.py:369} INFO - Running <TaskInstance: water_polution.model_preparation manual__2023-12-03T17:38:00.239033+00:00 [running]> on host MLops.myguest.virtualbox.org
[2023-12-03 22:53:26,054] {taskinstance.py:1569} INFO - Exporting the following env vars:
AIRFLOW_CTX_DAG_OWNER=Admin
AIRFLOW_CTX_DAG_ID=water_polution
AIRFLOW_CTX_TASK_ID=model_preparation
AIRFLOW_CTX_EXECUTION_DATE=2023-12-03T17:38:00.239033+00:00
AIRFLOW_CTX_TRY_NUMBER=1
AIRFLOW_CTX_DAG_RUN_ID=manual__2023-12-03T17:38:00.239033+00:00
[2023-12-03 22:53:26,063] {subprocess.py:62} INFO - Tmp dir root location: 
 /tmp
[2023-12-03 22:53:26,066] {subprocess.py:74} INFO - Running command: ['bash', '-c', 'python3 /home/antosha/project/scripts/model_preparation.py']
[2023-12-03 22:53:26,082] {subprocess.py:85} INFO - Output:
[2023-12-03 22:53:27,485] {subprocess.py:92} INFO - Traceback (most recent call last):
[2023-12-03 22:53:27,486] {subprocess.py:92} INFO -   File "/home/antosha/project/scripts/model_preparation.py", line 6, in <module>
[2023-12-03 22:53:27,486] {subprocess.py:92} INFO -     X_train = pd.read_csv('datasets/X_train.csv', delimiter = ',')
[2023-12-03 22:53:27,486] {subprocess.py:92} INFO -   File "/home/antosha/venvs/practice_3/lib/python3.10/site-packages/pandas/io/parsers/readers.py", line 948, in read_csv
[2023-12-03 22:53:27,487] {subprocess.py:92} INFO -     return _read(filepath_or_buffer, kwds)
[2023-12-03 22:53:27,487] {subprocess.py:92} INFO -   File "/home/antosha/venvs/practice_3/lib/python3.10/site-packages/pandas/io/parsers/readers.py", line 611, in _read
[2023-12-03 22:53:27,487] {subprocess.py:92} INFO -     parser = TextFileReader(filepath_or_buffer, **kwds)
[2023-12-03 22:53:27,487] {subprocess.py:92} INFO -   File "/home/antosha/venvs/practice_3/lib/python3.10/site-packages/pandas/io/parsers/readers.py", line 1448, in __init__
[2023-12-03 22:53:27,488] {subprocess.py:92} INFO -     self._engine = self._make_engine(f, self.engine)
[2023-12-03 22:53:27,488] {subprocess.py:92} INFO -   File "/home/antosha/venvs/practice_3/lib/python3.10/site-packages/pandas/io/parsers/readers.py", line 1705, in _make_engine
[2023-12-03 22:53:27,488] {subprocess.py:92} INFO -     self.handles = get_handle(
[2023-12-03 22:53:27,488] {subprocess.py:92} INFO -   File "/home/antosha/venvs/practice_3/lib/python3.10/site-packages/pandas/io/common.py", line 863, in get_handle
[2023-12-03 22:53:27,489] {subprocess.py:92} INFO -     handle = open(
[2023-12-03 22:53:27,490] {subprocess.py:92} INFO - FileNotFoundError: [Errno 2] No such file or directory: 'datasets/X_train.csv'
[2023-12-03 22:53:27,795] {subprocess.py:96} INFO - Command exited with return code 1
[2023-12-03 22:53:27,805] {taskinstance.py:1889} ERROR - Task failed with exception
Traceback (most recent call last):
  File "/home/antosha/venvs/practice_3/lib/python3.10/site-packages/airflow/operators/bash.py", line 194, in execute
    raise AirflowException(
airflow.exceptions.AirflowException: Bash command failed. The command returned a non-zero exit code 1.
[2023-12-03 22:53:27,812] {taskinstance.py:1395} INFO - Marking task as UP_FOR_RETRY. dag_id=water_polution, task_id=model_preparation, execution_date=20231203T173800, start_date=20231203T175325, end_date=20231203T175327
[2023-12-03 22:53:27,833] {standard_task_runner.py:92} ERROR - Failed to execute job 13 for task model_preparation (Bash command failed. The command returned a non-zero exit code 1.; 20539)
[2023-12-03 22:53:27,856] {local_task_job.py:156} INFO - Task exited with return code 1
[2023-12-03 22:53:27,898] {local_task_job.py:273} INFO - 0 downstream tasks scheduled from follow-on schedule check
