[2023-12-03 22:06:56,776] {taskinstance.py:1159} INFO - Dependencies all met for <TaskInstance: water_polution.data_creation manual__2023-12-03T17:01:49.179619+00:00 [queued]>
[2023-12-03 22:06:56,788] {taskinstance.py:1159} INFO - Dependencies all met for <TaskInstance: water_polution.data_creation manual__2023-12-03T17:01:49.179619+00:00 [queued]>
[2023-12-03 22:06:56,788] {taskinstance.py:1356} INFO - 
--------------------------------------------------------------------------------
[2023-12-03 22:06:56,788] {taskinstance.py:1357} INFO - Starting attempt 2 of 6
[2023-12-03 22:06:56,788] {taskinstance.py:1358} INFO - 
--------------------------------------------------------------------------------
[2023-12-03 22:06:56,809] {taskinstance.py:1377} INFO - Executing <Task(BashOperator): data_creation> on 2023-12-03 17:01:49.179619+00:00
[2023-12-03 22:06:56,824] {standard_task_runner.py:79} INFO - Running: ['airflow', 'tasks', 'run', 'water_polution', 'data_creation', 'manual__2023-12-03T17:01:49.179619+00:00', '--job-id', '4', '--raw', '--subdir', 'DAGS_FOLDER/water_polution.py', '--cfg-path', '/tmp/tmpi5kowbyz', '--error-file', '/tmp/tmpkl1dmgla']
[2023-12-03 22:06:56,825] {standard_task_runner.py:80} INFO - Job 4: Subtask data_creation
[2023-12-03 22:06:56,815] {standard_task_runner.py:52} INFO - Started process 12929 to run task
[2023-12-03 22:06:56,921] {task_command.py:369} INFO - Running <TaskInstance: water_polution.data_creation manual__2023-12-03T17:01:49.179619+00:00 [running]> on host MLops.myguest.virtualbox.org
[2023-12-03 22:06:57,051] {taskinstance.py:1569} INFO - Exporting the following env vars:
AIRFLOW_CTX_DAG_OWNER=Admin
AIRFLOW_CTX_DAG_ID=water_polution
AIRFLOW_CTX_TASK_ID=data_creation
AIRFLOW_CTX_EXECUTION_DATE=2023-12-03T17:01:49.179619+00:00
AIRFLOW_CTX_TRY_NUMBER=2
AIRFLOW_CTX_DAG_RUN_ID=manual__2023-12-03T17:01:49.179619+00:00
[2023-12-03 22:06:57,052] {subprocess.py:62} INFO - Tmp dir root location: 
 /tmp
[2023-12-03 22:06:57,055] {subprocess.py:74} INFO - Running command: ['bash', '-c', 'python3 /home/antosha/project/scripts/data_creation.py']
[2023-12-03 22:06:57,070] {subprocess.py:85} INFO - Output:
[2023-12-03 22:06:59,506] {subprocess.py:92} INFO - 
[2023-12-03 22:06:59,506] {subprocess.py:92} INFO -  	Cannot retrieve the public link of the file. You may need to change
[2023-12-03 22:06:59,506] {subprocess.py:92} INFO - 	the permission to 'Anyone with the link', or have had many accesses.
[2023-12-03 22:06:59,506] {subprocess.py:92} INFO - 
[2023-12-03 22:06:59,506] {subprocess.py:92} INFO - You may still be able to access the file from the browser:
[2023-12-03 22:06:59,507] {subprocess.py:92} INFO - 
[2023-12-03 22:06:59,507] {subprocess.py:92} INFO - 	 https://drive.google.com/uc?id=1waefPsrT7sm5rsRMjDHGCXreY45q9tcY
[2023-12-03 22:06:59,507] {subprocess.py:92} INFO - 
[2023-12-03 22:06:59,508] {subprocess.py:92} INFO - Access denied with the following error:
[2023-12-03 22:06:59,508] {subprocess.py:92} INFO - Traceback (most recent call last):
[2023-12-03 22:06:59,508] {subprocess.py:92} INFO -   File "/home/antosha/project/scripts/data_creation.py", line 8, in <module>
[2023-12-03 22:06:59,508] {subprocess.py:92} INFO -     df = pd.read_csv('datasets/dataset.csv', delimiter = ',', index_col = 0)
[2023-12-03 22:06:59,508] {subprocess.py:92} INFO -   File "/home/antosha/venvs/practice_3/lib/python3.10/site-packages/pandas/io/parsers/readers.py", line 948, in read_csv
[2023-12-03 22:06:59,509] {subprocess.py:92} INFO -     return _read(filepath_or_buffer, kwds)
[2023-12-03 22:06:59,509] {subprocess.py:92} INFO -   File "/home/antosha/venvs/practice_3/lib/python3.10/site-packages/pandas/io/parsers/readers.py", line 611, in _read
[2023-12-03 22:06:59,509] {subprocess.py:92} INFO -     parser = TextFileReader(filepath_or_buffer, **kwds)
[2023-12-03 22:06:59,509] {subprocess.py:92} INFO -   File "/home/antosha/venvs/practice_3/lib/python3.10/site-packages/pandas/io/parsers/readers.py", line 1448, in __init__
[2023-12-03 22:06:59,509] {subprocess.py:92} INFO -     self._engine = self._make_engine(f, self.engine)
[2023-12-03 22:06:59,509] {subprocess.py:92} INFO -   File "/home/antosha/venvs/practice_3/lib/python3.10/site-packages/pandas/io/parsers/readers.py", line 1705, in _make_engine
[2023-12-03 22:06:59,509] {subprocess.py:92} INFO -     self.handles = get_handle(
[2023-12-03 22:06:59,509] {subprocess.py:92} INFO -   File "/home/antosha/venvs/practice_3/lib/python3.10/site-packages/pandas/io/common.py", line 863, in get_handle
[2023-12-03 22:06:59,510] {subprocess.py:92} INFO -     handle = open(
[2023-12-03 22:06:59,512] {subprocess.py:92} INFO - FileNotFoundError: [Errno 2] No such file or directory: 'datasets/dataset.csv'
[2023-12-03 22:06:59,912] {subprocess.py:96} INFO - Command exited with return code 1
[2023-12-03 22:06:59,925] {taskinstance.py:1889} ERROR - Task failed with exception
Traceback (most recent call last):
  File "/home/antosha/venvs/practice_3/lib/python3.10/site-packages/airflow/operators/bash.py", line 194, in execute
    raise AirflowException(
airflow.exceptions.AirflowException: Bash command failed. The command returned a non-zero exit code 1.
[2023-12-03 22:06:59,931] {taskinstance.py:1395} INFO - Marking task as UP_FOR_RETRY. dag_id=water_polution, task_id=data_creation, execution_date=20231203T170149, start_date=20231203T170656, end_date=20231203T170659
[2023-12-03 22:06:59,951] {standard_task_runner.py:92} ERROR - Failed to execute job 4 for task data_creation (Bash command failed. The command returned a non-zero exit code 1.; 12929)
[2023-12-03 22:06:59,977] {local_task_job.py:156} INFO - Task exited with return code 1
[2023-12-03 22:07:00,013] {local_task_job.py:273} INFO - 0 downstream tasks scheduled from follow-on schedule check
