[2023-12-03 22:27:07,853] {taskinstance.py:1159} INFO - Dependencies all met for <TaskInstance: water_polution.data_creation manual__2023-12-03T17:01:49.179619+00:00 [queued]>
[2023-12-03 22:27:07,869] {taskinstance.py:1159} INFO - Dependencies all met for <TaskInstance: water_polution.data_creation manual__2023-12-03T17:01:49.179619+00:00 [queued]>
[2023-12-03 22:27:07,869] {taskinstance.py:1356} INFO - 
--------------------------------------------------------------------------------
[2023-12-03 22:27:07,869] {taskinstance.py:1357} INFO - Starting attempt 6 of 6
[2023-12-03 22:27:07,869] {taskinstance.py:1358} INFO - 
--------------------------------------------------------------------------------
[2023-12-03 22:27:07,895] {taskinstance.py:1377} INFO - Executing <Task(BashOperator): data_creation> on 2023-12-03 17:01:49.179619+00:00
[2023-12-03 22:27:07,898] {standard_task_runner.py:52} INFO - Started process 16152 to run task
[2023-12-03 22:27:07,912] {standard_task_runner.py:79} INFO - Running: ['airflow', 'tasks', 'run', 'water_polution', 'data_creation', 'manual__2023-12-03T17:01:49.179619+00:00', '--job-id', '8', '--raw', '--subdir', 'DAGS_FOLDER/water_polution.py', '--cfg-path', '/tmp/tmpitu9uny8', '--error-file', '/tmp/tmpurf9yii4']
[2023-12-03 22:27:07,913] {standard_task_runner.py:80} INFO - Job 8: Subtask data_creation
[2023-12-03 22:27:07,984] {task_command.py:369} INFO - Running <TaskInstance: water_polution.data_creation manual__2023-12-03T17:01:49.179619+00:00 [running]> on host MLops.myguest.virtualbox.org
[2023-12-03 22:27:08,060] {taskinstance.py:1569} INFO - Exporting the following env vars:
AIRFLOW_CTX_DAG_OWNER=Admin
AIRFLOW_CTX_DAG_ID=water_polution
AIRFLOW_CTX_TASK_ID=data_creation
AIRFLOW_CTX_EXECUTION_DATE=2023-12-03T17:01:49.179619+00:00
AIRFLOW_CTX_TRY_NUMBER=6
AIRFLOW_CTX_DAG_RUN_ID=manual__2023-12-03T17:01:49.179619+00:00
[2023-12-03 22:27:08,063] {subprocess.py:62} INFO - Tmp dir root location: 
 /tmp
[2023-12-03 22:27:08,063] {subprocess.py:74} INFO - Running command: ['bash', '-c', 'python3 /home/antosha/project/scripts/data_creation.py']
[2023-12-03 22:27:08,079] {subprocess.py:85} INFO - Output:
[2023-12-03 22:27:09,408] {subprocess.py:92} INFO - /home/antosha/venvs/practice_3/lib/python3.10/site-packages/gdown/parse_url.py:44: UserWarning: You specified a Google Drive link that is not the correct link to download a file. You might want to try `--fuzzy` option or the following url: https://drive.google.com/uc?id=19NlsU9_6qfc7q1gdG7Wi22jO7vhlpV07
[2023-12-03 22:27:09,408] {subprocess.py:92} INFO -   warnings.warn(
[2023-12-03 22:27:10,238] {subprocess.py:92} INFO - Traceback (most recent call last):
[2023-12-03 22:27:10,238] {subprocess.py:92} INFO -   File "/home/antosha/project/scripts/data_creation.py", line 6, in <module>
[2023-12-03 22:27:10,239] {subprocess.py:92} INFO -     gdown.download("https://drive.google.com/file/d/19NlsU9_6qfc7q1gdG7Wi22jO7vhlpV07/view?usp=drive_link", output="datasets/dataset.csv", quiet=False)
[2023-12-03 22:27:10,239] {subprocess.py:92} INFO -   File "/home/antosha/venvs/practice_3/lib/python3.10/site-packages/gdown/download.py", line 275, in download
[2023-12-03 22:27:10,239] {subprocess.py:92} INFO -     for file in os.listdir(osp.dirname(output) or "."):
[2023-12-03 22:27:10,239] {subprocess.py:92} INFO - FileNotFoundError: [Errno 2] No such file or directory: 'datasets'
[2023-12-03 22:27:10,584] {subprocess.py:96} INFO - Command exited with return code 1
[2023-12-03 22:27:10,599] {taskinstance.py:1889} ERROR - Task failed with exception
Traceback (most recent call last):
  File "/home/antosha/venvs/practice_3/lib/python3.10/site-packages/airflow/operators/bash.py", line 194, in execute
    raise AirflowException(
airflow.exceptions.AirflowException: Bash command failed. The command returned a non-zero exit code 1.
[2023-12-03 22:27:10,606] {taskinstance.py:1395} INFO - Marking task as FAILED. dag_id=water_polution, task_id=data_creation, execution_date=20231203T170149, start_date=20231203T172707, end_date=20231203T172710
[2023-12-03 22:27:10,622] {standard_task_runner.py:92} ERROR - Failed to execute job 8 for task data_creation (Bash command failed. The command returned a non-zero exit code 1.; 16152)
[2023-12-03 22:27:10,646] {local_task_job.py:156} INFO - Task exited with return code 1
[2023-12-03 22:27:10,689] {local_task_job.py:273} INFO - 0 downstream tasks scheduled from follow-on schedule check
